
raise new MyException()

try
	f()
end

try
	f()
finally
	print "FINALLY"
end


try
	f()
catch e
	print ("Exception has happened", e)
	a = 1
finally
	print ("There was an exception:", a)
end

# EOF
